~ # cd /opt/CTFd/
/opt/CTFd # gunicorn 'CTFd:create_app()' --bind '0.0.0.0:7999' --workers 1 --worker-class 'gevent'
[2018-05-08 16:50:55 +0000] [82] [INFO] Starting gunicorn 19.7.1
[2018-05-08 16:50:55 +0000] [82] [INFO] Listening at: http://0.0.0.0:7999 (82)
[2018-05-08 16:50:55 +0000] [82] [INFO] Using worker: gevent
[2018-05-08 16:50:55 +0000] [92] [INFO] Booting worker with pid: 92
[2018-05-08 16:50:56 +0000] [92] [ERROR] Non-ASCII character '\xc2' in file /opt/CTFd/CTFd/plugins/CTFd-intermediate-flag-plugin/__init__.py on line 207, but no encoding declared; see http://python.org/dev/peps/pep-0263/ for details (__init__.py, line 207)
Traceback (most recent call last):
  File "/usr/local/lib/python2.7/site-packages/gunicorn/workers/base.py", line 135, in load_wsgi
    self.wsgi = self.app.wsgi()
  File "/usr/local/lib/python2.7/site-packages/gunicorn/app/base.py", line 67, in wsgi
    self.callable = self.load()
  File "/usr/local/lib/python2.7/site-packages/gunicorn/app/wsgiapp.py", line 65, in load
    return self.load_wsgiapp()
  File "/usr/local/lib/python2.7/site-packages/gunicorn/app/wsgiapp.py", line 52, in load_wsgiapp
    return util.import_app(self.app_uri)
  File "/usr/local/lib/python2.7/site-packages/gunicorn/util.py", line 364, in import_app
    app = eval(obj, vars(mod))
  File "<string>", line 1, in <module>
  File "/opt/CTFd/CTFd/__init__.py", line 185, in create_app
    init_plugins(app)
  File "/opt/CTFd/CTFd/plugins/__init__.py", line 155, in init_plugins
    module = importlib.import_module(module, package='CTFd.plugins')
  File "/usr/local/lib/python2.7/importlib/__init__.py", line 37, in import_module
    __import__(name)
  File "/usr/local/lib/python2.7/site-packages/gevent/builtins.py", line 93, in __import__
    result = _import(*args, **kwargs)
  File "/opt/CTFd/CTFd/plugins/CTFd-intermediate-flag-plugin/__init__.py", line 207
SyntaxError: Non-ASCII character '\xc2' in file /opt/CTFd/CTFd/plugins/CTFd-intermediate-flag-plugin/__init__.py on line 207, but no encoding declared; see http://python.org/dev/peps/pep-0263/ for details
[2018-05-08 16:50:56 +0000] [92] [ERROR] Exception in worker process
Traceback (most recent call last):
  File "/usr/local/lib/python2.7/site-packages/gunicorn/arbiter.py", line 578, in spawn_worker
    worker.init_process()
  File "/usr/local/lib/python2.7/site-packages/gunicorn/workers/ggevent.py", line 190, in init_process
    super(GeventWorker, self).init_process()
  File "/usr/local/lib/python2.7/site-packages/gunicorn/workers/base.py", line 126, in init_process
    self.load_wsgi()
  File "/usr/local/lib/python2.7/site-packages/gunicorn/workers/base.py", line 148, in load_wsgi
    self.reloader.add_extra_file(exc_val.filename)
AttributeError: 'NoneType' object has no attribute 'add_extra_file'
[2018-05-08 16:50:56 +0000] [92] [INFO] Worker exiting (pid: 92)
[2018-05-08 16:50:56 +0000] [82] [INFO] Shutting down: Master
[2018-05-08 16:50:56 +0000] [82] [INFO] Reason: Worker failed to boot.
